<?xml version="1.0" encoding="utf-8"?>
<!-- =================================================================================== -->
<!-- |    This document was autogenerated by xacro from hand.urdf.xacro                | -->
<!-- |    EDITING THIS FILE BY HAND IS NOT RECOMMENDED                                 | -->
<!-- =================================================================================== -->
<robot name="hand">
  <link name="world"/>
  <!-- Link HAND -->
  <link name="panda_hand">
    <visual>
      <origin rpy="0 0 0" xyz="0 0 0"/>
      <geometry>
        <mesh filename="package://franka_description/meshes/franka/visual/hand.dae"/>
      </geometry>
    </visual>
    <collision>
      <origin rpy="0 0 0" xyz="0 0 0"/>
      <geometry>
        <mesh filename="package://franka_description/meshes/franka/collision/hand.stl"/>
      </geometry>
    </collision>
    <inertial>
      <!-- ATTENTION! Mass taken from ERDAL and inertia (scaled by mass) from mkrizmancic git! -->
      <origin rpy="0 0 0" xyz="0 0.0015244 0.0275912"/>
      <mass value="0.67893"/>
      <inertia ixx="0.00259072461603935959" ixy="0" ixz="0" iyy="0.00037201954518969459" iyz="0" izz="0.00238442114987670904"/>
    </inertial>
  </link>
  <gazebo reference="panda_hand">
    <material>Gazebo/White</material>
  </gazebo>
  <link name="panda_leftfinger">
    <visual>
      <geometry>
        <mesh filename="package://franka_description/meshes/franka/visual/finger.dae"/>
      </geometry>
    </visual>
    <collision>
      <geometry>
        <mesh filename="package://franka_description/meshes/franka/collision/finger.stl"/>
      </geometry>
      <contact_coefficient k_d="1" k_p="100" mu="10.0"/>
    </collision>
    <inertial>
      <!-- ATTENTION! Mass taken from ERDAL -->
      <origin rpy="0 0 0" xyz="0 0 0.02"/>
      <mass value="0.01053"/>
      <inertia ixx="0.001" ixy="0" ixz="0" iyy="0.001" iyz="0" izz="0.001"/>
    </inertial>
  </link>
  <link name="panda_rightfinger">
    <visual>
      <origin rpy="0 0 3.14159265359" xyz="0 0 0"/>
      <geometry>
        <mesh filename="package://franka_description/meshes/franka/visual/finger.dae"/>
      </geometry>
    </visual>
    <collision>
      <origin rpy="0 0 3.14159265359" xyz="0 0 0"/>
      <geometry>
        <mesh filename="package://franka_description/meshes/franka/collision/finger.stl"/>
      </geometry>
      <contact_coefficient k_d="1" k_p="100" mu="10.0"/>
    </collision>
    <inertial>
      <!-- ATTENTION! Mass taken from ERDAL -->
      <origin rpy="0 0 0" xyz="0 0 0.02"/>
      <mass value="0.01053"/>
      <inertia ixx="0.001" ixy="0" ixz="0" iyy="0.001" iyz="0" izz="0.001"/>
    </inertial>
  </link>
  <joint name="panda_finger_joint1" type="prismatic">
    <parent link="panda_hand"/>
    <child link="panda_leftfinger"/>
    <origin rpy="0 0 0" xyz="0 0 0.0584"/>
    <axis xyz="0 1 0"/>
    <limit effort="20" lower="0.0" upper="0.06" velocity="0.2"/>
    <dynamics damping="1" friction="0"/>
  </joint>
  <transmission name="panda_finger_transmission1">
    <robotNamespace>/</robotNamespace>
    <type>transmission_interface/SimpleTransmission</type>
    <joint name="panda_finger_joint1">
      <hardwareInterface>hardware_interface/EffortJointInterface</hardwareInterface>
    </joint>
    <actuator name="panda_finger_motor1">
      <hardwareInterface>hardware_interface/EffortJointInterface</hardwareInterface>
      <mechanicalReduction>1</mechanicalReduction>
    </actuator>
  </transmission>
  <joint name="panda_finger_joint2" type="prismatic">
    <parent link="panda_hand"/>
    <child link="panda_rightfinger"/>
    <origin rpy="0 0 0" xyz="0 0 0.0584"/>
    <axis xyz="0 -1 0"/>
    <limit effort="20" lower="0.0" upper="0.06" velocity="0.2"/>
    <dynamics damping="1" friction="0"/>
    <!-- <mimic joint="${ns}_finger_joint1" /> -->
    <!-- GAZEBO DOES NOT SUPPORT MIMIC JOINTS... -->
  </joint>
  <transmission name="panda_finger_transmission2">
    <robotNamespace>/</robotNamespace>
    <type>transmission_interface/SimpleTransmission</type>
    <joint name="panda_finger_joint2">
      <hardwareInterface>hardware_interface/EffortJointInterface</hardwareInterface>
    </joint>
    <actuator name="panda_finger_motor2">
      <hardwareInterface>hardware_interface/EffortJointInterface</hardwareInterface>
      <mechanicalReduction>1</mechanicalReduction>
    </actuator>
  </transmission>
  <link name="panda_tcp"/>
  <joint name="panda_hand_tcp_joint" type="fixed">
    <parent link="panda_hand"/>
    <child link="panda_tcp"/>
    <origin rpy="0 0 0" xyz="0 0 0.1025"/>
  </joint>
  <material name="Red">
    <color rgba="0.8 0.0 0.0 1.0"/>
  </material>
  <gazebo reference="panda_tcp">
    <material>Gazebo/Red</material>
  </gazebo>
  <gazebo reference="panda_leftfinger">
    <material>Gazebo/Black</material>
    <kp>1000000.0</kp>
    <kd>1.0</kd>
    <mu1>10.0</mu1>
    <mu2>10.0</mu2>
    <minDepth>0.001</minDepth>
  </gazebo>
  <gazebo reference="panda_rightfinger">
    <material>Gazebo/Black</material>
    <kp>1000000.0</kp>
    <kd>1.0</kd>
    <mu1>10.0</mu1>
    <mu2>10.0</mu2>
    <minDepth>0.001</minDepth>
  </gazebo>
  <gazebo reference="panda_finger_joint1">
    <implicitSpringDamper>1</implicitSpringDamper>
  </gazebo>
  <gazebo reference="panda_finger_joint2">
    <implicitSpringDamper>1</implicitSpringDamper>
  </gazebo>
  <!-- Adding the Camera -->
  <!-- joint between panda and the camera adopter -->
  <joint name="tool_adopter_joint" type="fixed">
    <parent link="panda_hand"/>
    <child link="adopter_link"/>
    <origin rpy="0 0 3.14159265359" xyz="0.063 0.03 0.0"/>
  </joint>
  <link name="adopter_link">
    <inertial>
      <mass value="0.2"/>
      <inertia ixx="0.001" ixy="0" ixz="0" iyy="0.001" iyz="0" izz="0.001"/>
    </inertial>
    <visual>
      <origin rpy="0 0 0" xyz="0 0 0"/>
      <geometry>
        <mesh filename="package://franka_description/meshes/camera_holder/Panda_RealSenseD435_Camera_Mount.stl" scale="0.001 0.001 0.001"/>
      </geometry>
    </visual>
    <collision>
      <origin rpy="0 0 0" xyz="0 0 0"/>
      <geometry>
        <box size="0.001 0.001 0.001"/>
      </geometry>
    </collision>
  </link>
  <!-- joint between panda and a camera -->
  <joint name="tool_camera_joint" type="fixed">
    <parent link="panda_hand"/>
    <child link="camera_link"/>
    <origin rpy="1.57079632679 -1.57079632679 1.57079632679" xyz="0.0665 -0.0192 0.0595"/>
  </joint>
  <link name="camera_link">
    <inertial>
      <mass value="0.2"/>
      <inertia ixx="0.001" ixy="0" ixz="0" iyy="0.001" iyz="0" izz="0.001"/>
    </inertial>
    <visual>
      <origin rpy="1.57079632679 0 1.57079632679" xyz="0.0006 -0.01931 -0.01638"/>
      <geometry>
        <mesh filename="package://franka_description/meshes/realsense_415/Intel_RealSense_Depth_Camera_D415.stl" scale="0.001 0.001 0.001"/>
      </geometry>
    </visual>
    <collision>
      <origin rpy="1.57079632679 0 1.57079632679" xyz="-0.0094 -0.01931 -0.01638"/>
      <geometry>
        <box size="0.099 0.023 0.02"/>
      </geometry>
    </collision>
  </link>
  <material name="Black">
    <color rgba="0.0 0.0 0.0 1.0"/>
  </material>
  <!-- Adding the camera to gazebo -->
  <!-- camera adopter -->
  <gazebo reference="adopter_link">
    <material>Gazebo/Black</material>
  </gazebo>
  <!-- camera -->
  <gazebo reference="camera_link">
    <sensor name="camera" type="depth">
      <update_rate>20</update_rate>
      <camera>
        <!-- <horizontal_fov>1.591740278</horizontal_fov> -->
        <!-- For realsense D435 - 91.2 degrees -->
        <!-- <horizontal_fov>1.211258501</horizontal_fov> -->
        <!-- For realsense D415 - 69.4 degrees -->
        <!-- <horizontal_fov>1.19646466766</horizontal_fov> -->
        <!--  For realsense D415 specific camera - 68.5523757935 degrees -->
        <horizontal_fov>1.184618483</horizontal_fov>
        <!--  For realsense D415 specific camera after reducing 1 percent - 67.8736394 degrees -->
        <image>
          <width>1280</width>
          <height>720</height>
          <format>R8G8B8</format>
        </image>
        <clip>
          <near>0.05</near>
          <far>3</far>
        </clip>
      </camera>
      <plugin filename="libgazebo_ros_openni_kinect.so" name="camera_plugin">
        <baseline>0.2</baseline>
        <alwaysOn>true</alwaysOn>
        <!-- Keep this zero, update_rate in the parent <sensor> tag
              will control the frame rate. -->
        <updateRate>0.0</updateRate>
        <cameraName>camera_ir</cameraName>
        <imageTopicName>/camera/rgb_image</imageTopicName>
        <cameraInfoTopicName>/camera/rgb_camera_info</cameraInfoTopicName>
        <depthImageTopicName>/camera/depth_image</depthImageTopicName>
        <depthImageInfoTopicName>/camera/depth_camera_info</depthImageInfoTopicName>
        <pointCloudTopicName>/camera/points</pointCloudTopicName>
        <frameName>camera_ir</frameName>
        <pointCloudCutoff>0.05</pointCloudCutoff>
        <distortionK1>0</distortionK1>
        <distortionK2>0</distortionK2>
        <distortionK3>0</distortionK3>
        <distortionT1>0</distortionT1>
        <distortionT2>0</distortionT2>
        <CxPrime>0</CxPrime>
        <Cx>0</Cx>
        <Cy>0</Cy>
        <focalLength>0</focalLength>
        <hackBaseline>0</hackBaseline>
      </plugin>
    </sensor>
  </gazebo>
  <!-- Load gripper plugin. This plugin fixes an object which is grasped to the
         robot hand to avoid problems with physics engines and to help the object
         stay in the robot hand without slipping out -->
  <gazebo>
    <plugin filename="libgazebo_grasp_fix.so" name="gazebo_grasp_fix">
      <arm>
        <arm_name>gripper</arm_name>
        <palm_link>panda_link7</palm_link>
        <gripper_link>panda_leftfinger</gripper_link>
        <gripper_link>panda_rightfinger</gripper_link>
      </arm>
      <forces_angle_tolerance>90</forces_angle_tolerance>
      <update_rate>25</update_rate>
      <grip_count_threshold>4</grip_count_threshold>
      <max_grip_count>8</max_grip_count>
      <release_tolerance>0.001</release_tolerance>
      <disable_collisions_on_attach>false</disable_collisions_on_attach>
      <contact_topic>__default_topic__</contact_topic>
    </plugin>
  </gazebo>
  <gazebo>
    <plugin filename="libgazebo_ros_control.so" name="gazebo_ros_control">
      <robotNamespace>/</robotNamespace>
    </plugin>
  </gazebo>
</robot>
