<?xml version="1.0" ?>
<!-- =================================================================================== -->
<!-- |    This document was autogenerated by xacro from panda_arm.urdf.xacro           | -->
<!-- |    EDITING THIS FILE BY HAND IS NOT RECOMMENDED                                 | -->
<!-- =================================================================================== -->
<robot name="panda" xmlns:xacro="http://www.ros.org/wiki/xacro">
  <link name="world"/>
  <joint name="panda_joint_world" type="fixed">
    <parent link="world"/>
    <child link="panda_link0"/>
    <origin rpy="0 0 0" xyz="0 0 0"/>
  </joint>
  <!-- LINK 0 -->
  <link name="panda_link0">
    <visual>
      <origin rpy="0 0 0" xyz="0 0 0"/>
      <geometry>
        <mesh filename="package://franka_description/meshes/franka/visual/link0.dae.dae"/>
      </geometry>
    </visual>
    <collision>
      <origin rpy="0 0 0" xyz="0 0 0"/>
      <geometry>
        <mesh filename="package://franka_description/meshes/franka/collision/link0.stl"/>
      </geometry>
    </collision>
    <inertial>
      <!-- ATTENTION! Copied from git of mkrizmancic -->
      <mass value="2.92"/>
      <origin rpy="0 0 0" xyz="-0.025566 -2.88e-05 0.057332"/>
      <inertia ixx="0.00782229414331" ixy="-1.56191622996e-05" ixz="-0.00126005738123" iyy="0.0109027971813" iyz="1.08233858202e-05" izz="0.0102355503949"/>
    </inertial>
  </link>
  <gazebo reference="panda_link0">
    <kp>1000000.0</kp>
    <kd>1.0</kd>
    <mu1>0.8</mu1>
    <mu2>0.8</mu2>
    <maxVel>0.0</maxVel>
    <minDepth>0.001</minDepth>
  </gazebo>
  <!-- LINK 1 -->
  <link name="panda_link1">
    <visual>
      <origin rpy="0 0 0" xyz="0 0 0"/>
      <geometry>
        <mesh filename="package://franka_description/meshes/franka/visual/link1.dae.dae"/>
      </geometry>
    </visual>
    <collision>
      <origin rpy="0 0 0" xyz="0 0 0"/>
      <geometry>
        <mesh filename="package://franka_description/meshes/franka/collision/link1.stl"/>
      </geometry>
    </collision>
    <inertial>
      <!-- ATTENTION! Copied from git of mkrizmancic -->
      <mass value="2.74"/>
      <origin rpy="0 0 0" xyz="0 -0.0324958 -0.0675818"/>
      <inertia ixx="0.0180416958283" ixy="0.0" ixz="0.0" iyy="0.0159136071891" iyz="0.0046758424612" izz="0.00620690827127"/>
    </inertial>
  </link>
  <gazebo reference="panda_link1">
    <kp>1000000.0</kp>
    <kd>1.0</kd>
    <mu1>0.8</mu1>
    <mu2>0.8</mu2>
    <maxVel>0.0</maxVel>
    <minDepth>0.001</minDepth>
  </gazebo>
  <joint name="panda_joint1" type="revolute">
    <safety_controller k_position="100.0" k_velocity="40.0" soft_lower_limit="-2.8973" soft_upper_limit="2.8973"/>
    <origin rpy="0 0 0" xyz="0 0 0.333"/>
    <parent link="panda_link0"/>
    <child link="panda_link1"/>
    <axis xyz="0 0 1"/>
    <limit effort="87" lower="-2.8973" upper="2.8973" velocity="2.1750"/>
    <dynamics damping="0.5" friction="1.0"/>
  </joint>
  <transmission name="panda_transmission1">
    <robotNamespace>/</robotNamespace>
    <type>transmission_interface/SimpleTransmission</type>
    <joint name="panda_joint1">
      <hardwareInterface>hardware_interface/PositionJointInterface</hardwareInterface>
    </joint>
    <actuator name="panda_motor1">
      <hardwareInterface>hardware_interface/PositionJointInterface</hardwareInterface>
      <mechanicalReduction>1</mechanicalReduction>
    </actuator>
  </transmission>
  <!-- LINK 2 -->
  <link name="panda_link2">
    <visual>
      <origin rpy="0 0 0" xyz="0 0 0"/>
      <geometry>
        <mesh filename="package://franka_description/meshes/franka/visual/link2.dae.dae"/>
      </geometry>
    </visual>
    <collision>
      <origin rpy="0 0 0" xyz="0 0 0"/>
      <geometry>
        <mesh filename="package://franka_description/meshes/franka/collision/link2.stl"/>
      </geometry>
    </collision>
    <inertial>
      <!-- ATTENTION! Copied from git of mkrizmancic -->
      <mass value="2.74"/>
      <origin rpy="0 0 0" xyz="0 -0.06861 0.0322285"/>
      <inertia ixx="0.0182856182281" ixy="0.0" ixz="0.0" iyy="0.00621358421175" iyz="-0.00472844221905" izz="0.0161514346309"/>
    </inertial>
  </link>
  <gazebo reference="panda_link2">
    <kp>1000000.0</kp>
    <kd>1.0</kd>
    <mu1>0.8</mu1>
    <mu2>0.8</mu2>
    <maxVel>0.0</maxVel>
    <minDepth>0.001</minDepth>
  </gazebo>
  <joint name="panda_joint2" type="revolute">
    <safety_controller k_position="100.0" k_velocity="40.0" soft_lower_limit="-1.7628" soft_upper_limit="1.7628"/>
    <origin rpy="-1.57079632679 0 0" xyz="0 0 0"/>
    <parent link="panda_link1"/>
    <child link="panda_link2"/>
    <axis xyz="0 0 1"/>
    <limit effort="87" lower="-1.7628" upper="1.7628" velocity="2.1750"/>
    <dynamics damping="0.5" friction="1.0"/>
  </joint>
  <transmission name="panda_transmission2">
    <robotNamespace>/</robotNamespace>
    <type>transmission_interface/SimpleTransmission</type>
    <joint name="panda_joint2">
      <hardwareInterface>hardware_interface/PositionJointInterface</hardwareInterface>
    </joint>
    <actuator name="panda_motor2">
      <hardwareInterface>hardware_interface/PositionJointInterface</hardwareInterface>
      <mechanicalReduction>1</mechanicalReduction>
    </actuator>
  </transmission>
  <!-- LINK 3 -->
  <link name="panda_link3">
    <visual>
      <origin rpy="0 0 0" xyz="0 0 0"/>
      <geometry>
        <mesh filename="package://franka_description/meshes/franka/visual/link3.dae.dae"/>
      </geometry>
    </visual>
    <collision>
      <origin rpy="0 0 0" xyz="0 0 0"/>
      <geometry>
        <mesh filename="package://franka_description/meshes/franka/collision/link3.stl"/>
      </geometry>
    </collision>
    <inertial>
      <!-- ATTENTION! Copied from git of mkrizmancic -->
      <mass value="2.38"/>
      <origin rpy="0 0 0" xyz="0.0469893 0.0316374 -0.031704"/>
      <inertia ixx="0.00771376630908" ixy="-0.00248490625138" ixz="-0.00332147581033" iyy="0.00989108008727" iyz="-0.00217796151484" izz="0.00811723558464"/>
    </inertial>
  </link>
  <gazebo reference="panda_link3">
    <kp>1000000.0</kp>
    <kd>1.0</kd>
    <mu1>0.8</mu1>
    <mu2>0.8</mu2>
    <maxVel>0.0</maxVel>
    <minDepth>0.001</minDepth>
  </gazebo>
  <joint name="panda_joint3" type="revolute">
    <safety_controller k_position="100.0" k_velocity="40.0" soft_lower_limit="-2.8973" soft_upper_limit="2.8973"/>
    <origin rpy="1.57079632679 0 0" xyz="0 -0.316 0"/>
    <parent link="panda_link2"/>
    <child link="panda_link3"/>
    <axis xyz="0 0 1"/>
    <limit effort="87" lower="-2.8973" upper="2.8973" velocity="2.1750"/>
    <dynamics damping="0.5" friction="1.0"/>
  </joint>
  <transmission name="panda_transmission3">
    <robotNamespace>/</robotNamespace>
    <type>transmission_interface/SimpleTransmission</type>
    <joint name="panda_joint3">
      <hardwareInterface>hardware_interface/PositionJointInterface</hardwareInterface>
    </joint>
    <actuator name="panda_motor3">
      <hardwareInterface>hardware_interface/PositionJointInterface</hardwareInterface>
      <mechanicalReduction>1</mechanicalReduction>
    </actuator>
  </transmission>
  <!-- LINK 4 -->
  <link name="panda_link4">
    <visual>
      <origin rpy="0 0 0" xyz="0 0 0"/>
      <geometry>
        <mesh filename="package://franka_description/meshes/franka/visual/link4.dae.dae"/>
      </geometry>
    </visual>
    <collision>
      <origin rpy="0 0 0" xyz="0 0 0"/>
      <geometry>
        <mesh filename="package://franka_description/meshes/franka/collision/link4.stl"/>
      </geometry>
    </collision>
    <inertial>
      <!-- ATTENTION! Copied from git of mkrizmancic -->
      <mass value="2.38"/>
      <origin rpy="0 0 0" xyz="-0.0360446 0.0336853 0.031882"/>
      <inertia ixx="0.00799663881132" ixy="0.00347095570217" ixz="-0.00241222942995" iyy="0.00825390705278" iyz="0.00235774044121" izz="0.0102515004345"/>
    </inertial>
  </link>
  <gazebo reference="panda_link4">
    <kp>1000000.0</kp>
    <kd>1.0</kd>
    <mu1>0.8</mu1>
    <mu2>0.8</mu2>
    <maxVel>0.0</maxVel>
    <minDepth>0.001</minDepth>
  </gazebo>
  <joint name="panda_joint4" type="revolute">
    <safety_controller k_position="100.0" k_velocity="40.0" soft_lower_limit="-3.0718" soft_upper_limit="-0.0698"/>
    <origin rpy="1.57079632679 0 0" xyz="0.0825 0 0"/>
    <parent link="panda_link3"/>
    <child link="panda_link4"/>
    <axis xyz="0 0 1"/>
    <limit effort="87" lower="-3.0718" upper="-0.0698" velocity="2.1750"/>
    <dynamics damping="0.5" friction="1.0"/>
  </joint>
  <transmission name="panda_transmission4">
    <robotNamespace>/</robotNamespace>
    <type>transmission_interface/SimpleTransmission</type>
    <joint name="panda_joint4">
      <hardwareInterface>hardware_interface/PositionJointInterface</hardwareInterface>
    </joint>
    <actuator name="panda_motor4">
      <hardwareInterface>hardware_interface/PositionJointInterface</hardwareInterface>
      <mechanicalReduction>1</mechanicalReduction>
    </actuator>
  </transmission>
  <!-- LINK 5 -->
  <link name="panda_link5">
    <visual>
      <origin rpy="0 0 0" xyz="0 0 0"/>
      <geometry>
        <mesh filename="package://franka_description/meshes/franka/visual/link5.dae.dae"/>
      </geometry>
    </visual>
    <collision>
      <origin rpy="0 0 0" xyz="0 0 0"/>
      <geometry>
        <mesh filename="package://franka_description/meshes/franka/collision/link5.stl"/>
      </geometry>
    </collision>
    <inertial>
      <!-- ATTENTION! Copied from git of mkrizmancic -->
      <mass value="2.74"/>
      <origin rpy="0 0 0" xyz="0 0.0610427 -0.104176"/>
      <inertia ixx="0.030371374513" ixy="6.50283587108e-07" ixz="-1.05129179916e-05" iyy="0.0288752887402" iyz="-0.00775653445787" izz="0.00444134056164"/>
    </inertial>
  </link>
  <gazebo reference="panda_link5">
    <kp>1000000.0</kp>
    <kd>1.0</kd>
    <mu1>0.8</mu1>
    <mu2>0.8</mu2>
    <maxVel>0.0</maxVel>
    <minDepth>0.001</minDepth>
  </gazebo>
  <joint name="panda_joint5" type="revolute">
    <safety_controller k_position="100.0" k_velocity="40.0" soft_lower_limit="-2.8973" soft_upper_limit="2.8973"/>
    <origin rpy="-1.57079632679 0 0" xyz="-0.0825 0.384 0"/>
    <parent link="panda_link4"/>
    <child link="panda_link5"/>
    <axis xyz="0 0 1"/>
    <limit effort="12" lower="-2.8973" upper="2.8973" velocity="2.6100"/>
    <dynamics damping="0.5" friction="1.0"/>
  </joint>
  <transmission name="panda_transmission5">
    <robotNamespace>/</robotNamespace>
    <type>transmission_interface/SimpleTransmission</type>
    <joint name="panda_joint5">
      <hardwareInterface>hardware_interface/PositionJointInterface</hardwareInterface>
    </joint>
    <actuator name="panda_motor5">
      <hardwareInterface>hardware_interface/PositionJointInterface</hardwareInterface>
      <mechanicalReduction>1</mechanicalReduction>
    </actuator>
  </transmission>
  <!-- LINK 6 -->
  <link name="panda_link6">
    <visual>
      <origin rpy="0 0 0" xyz="0 0 0.0"/>
      <geometry>
        <mesh filename="package://franka_description/meshes/franka/visual/link6.dae.dae"/>
      </geometry>
    </visual>
    <collision>
      <origin rpy="0 0 0" xyz="0 0 0.0"/>
      <geometry>
        <mesh filename="package://franka_description/meshes/franka/collision/link6.stl"/>
      </geometry>
    </collision>
    <inertial>
      <!-- ATTENTION! Copied from git of mkrizmancic -->
      <mass value="1.55"/>
      <origin rpy="0 0 0" xyz="0.0510509 0.009108 0.0106343"/>
      <inertia ixx="0.00303336450376" ixy="-0.000437276865508" ixz="0.000629257294877" iyy="0.00404479911567" iyz="0.000130472021025" izz="0.00558234286039"/>
    </inertial>
  </link>
  <gazebo reference="panda_link6">
    <kp>1000000.0</kp>
    <kd>1.0</kd>
    <mu1>0.8</mu1>
    <mu2>0.8</mu2>
    <maxVel>0.0</maxVel>
    <minDepth>0.001</minDepth>
  </gazebo>
  <joint name="panda_joint6" type="revolute">
    <safety_controller k_position="100.0" k_velocity="40.0" soft_lower_limit="-0.0175" soft_upper_limit="3.7525"/>
    <origin rpy="1.57079632679 0 0" xyz="0 0 0"/>
    <parent link="panda_link5"/>
    <child link="panda_link6"/>
    <axis xyz="0 0 1"/>
    <limit effort="12" lower="-0.0175" upper="3.7525" velocity="2.6100"/>
    <dynamics damping="0.5" friction="1.0"/>
  </joint>
  <transmission name="panda_transmission6">
    <robotNamespace>/</robotNamespace>
    <type>transmission_interface/SimpleTransmission</type>
    <joint name="panda_joint6">
      <hardwareInterface>hardware_interface/PositionJointInterface</hardwareInterface>
    </joint>
    <actuator name="panda_motor6">
      <hardwareInterface>hardware_interface/PositionJointInterface</hardwareInterface>
      <mechanicalReduction>1</mechanicalReduction>
    </actuator>
  </transmission>
  <!-- LINK 7 -->
  <link name="panda_link7">
    <visual>
      <origin xyz="0 0 0"/>
      <geometry>
        <mesh filename="package://franka_description/meshes/franka/visual/link7.dae.dae"/>
      </geometry>
    </visual>
    <collision>
      <origin xyz="0 0 0"/>
      <geometry>
        <mesh filename="package://franka_description/meshes/franka/collision/link7.stl"/>
      </geometry>
    </collision>
    <inertial>
      <!-- ATTENTION! Copied from git of mkrizmancic -->
      <mass value="0.54"/>
      <origin rpy="0 0 0" xyz="0.0109695 0.0107965 0.0650411"/>
      <inertia ixx="0.000888868887021" ixy="-0.00012239074652" ixz="3.98699829666e-05" iyy="0.000888001373233" iyz="-9.33825115206e-05" izz="0.0007176834609"/>
    </inertial>
  </link>
  <gazebo reference="panda_link7">
    <kp>1000000.0</kp>
    <kd>1.0</kd>
    <mu1>0.8</mu1>
    <mu2>0.8</mu2>
    <maxVel>0.0</maxVel>
    <minDepth>0.001</minDepth>
  </gazebo>
  <joint name="panda_joint7" type="revolute">
    <safety_controller k_position="100.0" k_velocity="40.0" soft_lower_limit="-2.8973" soft_upper_limit="2.8973"/>
    <origin rpy="1.57079632679 0 0" xyz="0.088 0 0"/>
    <parent link="panda_link6"/>
    <child link="panda_link7"/>
    <axis xyz="0 0 1"/>
    <limit effort="12" lower="-2.8973" upper="2.8973" velocity="2.6100"/>
    <dynamics damping="0.5" friction="1.0"/>
  </joint>
  <transmission name="panda_transmission7">
    <robotNamespace>/</robotNamespace>
    <type>transmission_interface/SimpleTransmission</type>
    <joint name="panda_joint7">
      <hardwareInterface>hardware_interface/PositionJointInterface</hardwareInterface>
    </joint>
    <actuator name="panda_motor7">
      <hardwareInterface>hardware_interface/PositionJointInterface</hardwareInterface>
      <mechanicalReduction>1</mechanicalReduction>
    </actuator>
  </transmission>
  <!-- LINK 8 (ROBOT FLANGE / EEF Link for CTRL) -->
  <link name="panda_link8"/>
  <joint name="panda_joint8" type="fixed">
    <origin rpy="0 0 0" xyz="0 0 0.107"/>
    <!-- z=0.107 IS THE ROBOT FLANGE. add +0.1025 to be the gripper TCP (if hand is connected to link7 instead of 8) -->
    <parent link="panda_link7"/>
    <child link="panda_link8"/>
    <axis xyz="0 0 0"/>
  </joint> 
    <gazebo reference="${arm_id}_link8">
      <material>Gazebo/White</material>
      <kp>1000000.0</kp>
      <kd>1.0</kd>
      <mu1>0.8</mu1>
      <mu2>0.8</mu2>
      <maxVel>0.0</maxVel>
      <minDepth>0.001</minDepth>
    </gazebo>
<!-- LINK 9 (EEF Link for CTRL) now: rotated s.t. same in IIWA (due to image coordinate system)-->
    <link name="${arm_id}_link9"/>
    <joint name="${arm_id}_joint9" type="fixed">
      <origin rpy="0 0 0.78539816339" xyz="0 0 ${0.1025}"/> 
      <parent link="${arm_id}_link8"/>
      <child link="${arm_id}_link9"/>
      <axis xyz="0 0 0"/>
    </joint>
    <gazebo reference="${arm_id}_link9">
      <material>Gazebo/White</material>
      <kp>1000000.0</kp>
      <kd>1.0</kd>
      <mu1>0.8</mu1>
      <mu2>0.8</mu2>
      <maxVel>0.0</maxVel>
      <minDepth>0.001</minDepth>
    </gazebo>
  <gazebo>
    <plugin filename="libgazebo_ros_control.so" name="gazebo_ros_control">
      <robotNamespace>/</robotNamespace>
    </plugin>
  </gazebo>
</robot>
